<?xml version="1.0" ?>
<!-- =================================================================================== -->
<!-- |    This document was autogenerated by xacro from limo_four_diff.xacro           | -->
<!-- |    EDITING THIS FILE BY HAND IS NOT RECOMMENDED                                 | -->
<!-- =================================================================================== -->
<robot name="limo_four_diff">
  <!-- <xacro:include filename="$(find limo_description)/urdf/limo_four_diff_2.gazebo" /> -->
  <link name="base_footprint"/>
  <joint name="base_joint" type="fixed">
    <parent link="base_footprint"/>
    <child link="base_link"/>
    <origin rpy="0 0 0" xyz="0.0 0.0 0.15"/>
  </joint>
  <!-- Base link -->
  <link name="base_link">
    <visual>
      <origin rpy="0 0 1.57" xyz="0 0 -0.15"/>
      <geometry>
        <mesh filename="file:///home/matt/ros2_ws/install/limo_description/share/limo_description/meshes/limo_base.dae" scale="1 1 1"/>
      </geometry>
    </visual>
    <collision>
      <!--origin xyz="0 0 -0.15" rpy="0 0 1.57" /-->
      <origin rpy="0 0 0" xyz="0 0 0"/>
      <geometry>
        <box size="0.13 0.12 0.1"/>
      </geometry>
    </collision>
  </link>
  <link name="inertial_link">
    <inertial>
      <origin xyz="0.0 0.0 0.0"/>
      <mass value="2.1557"/>
      <inertia ixx="0.24" ixy="0" ixz="0" iyy="0.96" iyz="0" izz="0.96"/>
    </inertial>
  </link>
  <joint name="inertial_joint" type="fixed">
    <origin rpy="0 0 0" xyz="0 0 0"/>
    <parent link="base_link"/>
    <child link="inertial_link"/>
  </joint>
  <link name="laser_link">
    <pose>0 0 0 0 0 0</pose>
    <inertial>
      <mass value="0.1"/>
      <origin rpy="0 0 0" xyz="0.0 0 0"/>
      <inertia ixx="1e-6" ixy="0" ixz="0" iyy="1e-6" iyz="0" izz="1e-6"/>
    </inertial>
    <visual name="laser_visual">
      <origin rpy="0 0 0" xyz="0 0 0"/>
      <geometry>
        <cylinder length="0.01" radius="0.02"/>
      </geometry>
      <material name="laser_material">
        <ambient>0.1 0.1 0.1 1</ambient>
        <diffuse>0.1 0.1 0.2 1</diffuse>
        <specular>0 0 0 0</specular>
        <emissive>0 0 0 1</emissive>
      </material>
    </visual>
    <collision name="laser_collision">
      <origin rpy="0 0 0" xyz="0 0 0"/>
      <geometry>
        <cylinder length="0.016" radius="0.032"/>
      </geometry>
    </collision>
  </link>
  <joint name="laser_joint" type="fixed">
    <origin rpy="0 0 0" xyz="0.103 0 -0.034"/>
    <child link="laser_link"/>
    <parent link="base_link"/>
  </joint>
  <gazebo reference="laser_link">
    <material>Gazebo/Yellow</material>
  </gazebo>
  <link name="depth_camera_link">
    <pose>0 0 0 0 0 0</pose>
    <inertial>
      <mass value="0.1"/>
      <origin rpy="0 0 0" xyz="0.0 0 0"/>
      <inertia ixx="1e-6" ixy="0" ixz="0" iyy="1e-6" iyz="0" izz="1e-6"/>
    </inertial>
    <visual name="depth_camera_visual">
      <origin rpy="0 0 0" xyz="0 0 0"/>
      <geometry>
        <box size="0.02 0.06 0.015"/>
      </geometry>
      <material name="depth_camera_material">
        <ambient>0.1 0.1 0.1 1</ambient>
        <diffuse>0.1 0.1 0.2 1</diffuse>
        <specular>0 0 0 0</specular>
        <emissive>0 0 0 1</emissive>
      </material>
    </visual>
    <collision name="depth_camera_collision">
      <origin rpy="0 0 0" xyz="0 0 0"/>
      <geometry>
        <box size="0.02 0.06 0.015"/>
      </geometry>
    </collision>
  </link>
  <joint name="depth_camera_joint" type="fixed">
    <origin rpy="0 0 0" xyz="0.084 0 0.3"/>
    <child link="depth_camera_link"/>
    <parent link="base_link"/>
  </joint>
  <link name="depth_link"/>
  <joint name="depth_camera_to_camera_joint" type="fixed">
    <origin rpy="-1.570795 0 -1.570795 " xyz="0 0 0"/>
    <parent link="depth_camera_link"/>
    <child link="depth_link"/>
  </joint>
  <gazebo reference="depth_camera_link">
    <material>Gazebo/Yellow</material>
  </gazebo>
  <link name="imu_link">
    <pose>0 0 0 0 0 0</pose>
    <inertial>
      <mass value="0.01"/>
      <origin rpy="0 0 0" xyz="0.0 0 0"/>
      <inertia ixx="1e-7" ixy="0" ixz="0" iyy="1e-7" iyz="0" izz="1e-7"/>
    </inertial>
    <visual name="imu_visual">
      <origin rpy="0 0 0" xyz="0 0 0"/>
      <geometry>
        <box size="0.001 0.001 0.001"/>
      </geometry>
      <material name="imu_material">
        <ambient>0.1 0.1 0.1 1</ambient>
        <diffuse>0.1 0.1 0.2 1</diffuse>
        <specular>0 0 0 0</specular>
        <emissive>0 0 0 1</emissive>
      </material>
    </visual>
    <collision name="imu_collision">
      <origin rpy="0 0 0" xyz="0 0 0"/>
      <geometry>
        <box size="0.001 0.001 0.001"/>
      </geometry>
    </collision>
  </link>
  <joint name="imu_joint" type="fixed">
    <origin rpy="0 0 0" xyz="0.0 0 -0.1"/>
    <child link="imu_link"/>
    <parent link="base_link"/>
  </joint>
  <gazebo reference="imu_link">
    <material>Gazebo/Yellow</material>
  </gazebo>
  <link name="front_left_wheel_link">
    <inertial>
      <origin xyz="0 0 0"/>
      <mass value="0.5"/>
      <inertia ixx="0.01055" ixy="0" ixz="0" iyy="0.00075" iyz="0" izz="0.01055"/>
    </inertial>
    <visual>
      <origin rpy="0 0 0" xyz="0 0 0"/>
      <geometry>
        <mesh filename="file:///home/matt/ros2_ws/install/limo_description/share/limo_description/meshes/limo_wheel.dae"/>
      </geometry>
      <material name="front_left_wheel_material">
        <color rgba="0.2 0.2 0.2 1"/>
      </material>
    </visual>
    <collision>
      <origin rpy="1.57 0 0" xyz="0 0.0225 0"/>
      <geometry>
        <cylinder length="0.045" radius="0.045"/>
      </geometry>
    </collision>
  </link>
  <joint name="front_left_wheel" type="continuous">
    <parent link="base_link"/>
    <child link="front_left_wheel_link"/>
    <origin rpy="0 0  0" xyz="0.1 0.065 -0.1"/>
    <axis xyz="0 1 0"/>
  </joint>
  <link name="front_right_wheel_link">
    <inertial>
      <origin xyz="0 0 0"/>
      <mass value="0.5"/>
      <inertia ixx="0.01055" ixy="0" ixz="0" iyy="0.00075" iyz="0" izz="0.01055"/>
    </inertial>
    <visual>
      <origin rpy="0 0 0" xyz="0 0 0"/>
      <geometry>
        <mesh filename="file:///home/matt/ros2_ws/install/limo_description/share/limo_description/meshes/limo_wheel.dae"/>
      </geometry>
      <material name="front_right_wheel_material">
        <color rgba="0.2 0.2 0.2 1"/>
      </material>
    </visual>
    <collision>
      <origin rpy="1.57 0 0" xyz="0 0.0225 0"/>
      <geometry>
        <cylinder length="0.045" radius="0.045"/>
      </geometry>
    </collision>
  </link>
  <joint name="front_right_wheel" type="continuous">
    <parent link="base_link"/>
    <child link="front_right_wheel_link"/>
    <origin rpy="3.14159 0 0" xyz="0.1 -0.065 -0.1"/>
    <axis xyz="0 -1 0"/>
  </joint>
  <link name="rear_left_wheel_link">
    <inertial>
      <origin xyz="0 0 0"/>
      <mass value="0.5"/>
      <inertia ixx="0.01055" ixy="0" ixz="0" iyy="0.00075" iyz="0" izz="0.01055"/>
    </inertial>
    <visual>
      <origin rpy="0 0 0" xyz="0 0 0"/>
      <geometry>
        <mesh filename="file:///home/matt/ros2_ws/install/limo_description/share/limo_description/meshes/limo_wheel.dae"/>
      </geometry>
      <material name="rear_left_wheel_material">
        <color rgba="0.2 0.2 0.2 1"/>
      </material>
    </visual>
    <collision>
      <origin rpy="1.57 0 0" xyz="0 0.0225 0"/>
      <geometry>
        <cylinder length="0.045" radius="0.045"/>
      </geometry>
    </collision>
  </link>
  <joint name="rear_left_wheel" type="continuous">
    <parent link="base_link"/>
    <child link="rear_left_wheel_link"/>
    <origin rpy="0 0 0" xyz="-0.1 0.065 -0.1"/>
    <axis xyz="0 1 0"/>
  </joint>
  <link name="rear_right_wheel_link">
    <inertial>
      <origin xyz="0 0 0"/>
      <mass value="0.5"/>
      <inertia ixx="0.01055" ixy="0" ixz="0" iyy="0.00075" iyz="0" izz="0.01055"/>
    </inertial>
    <visual>
      <origin rpy="0 0 0" xyz="0 0 0"/>
      <geometry>
        <mesh filename="file:///home/matt/ros2_ws/install/limo_description/share/limo_description/meshes/limo_wheel.dae"/>
      </geometry>
      <material name="rear_right_wheel_material">
        <color rgba="0.2 0.2 0.2 1"/>
      </material>
    </visual>
    <collision>
      <origin rpy="1.57 0 0" xyz="0 0.0225 0"/>
      <geometry>
        <cylinder length="0.045" radius="0.045"/>
      </geometry>
    </collision>
  </link>
  <joint name="rear_right_wheel" type="continuous">
    <parent link="base_link"/>
    <child link="rear_right_wheel_link"/>
    <origin rpy="3.14159 0 0" xyz="-0.1 -0.065 -0.1"/>
    <axis xyz="0 -1 0"/>
  </joint>
  <gazebo reference="imu_link">
  <gravity>true</gravity>
  <sensor name="imu_sensor" type="imu">
    <always_on>true</always_on>
    <update_rate>100</update_rate>
    <visualize>true</visualize>
    <imu>
      <orientation>
        <x>
          <noise type="gaussian">
            <mean>0.0</mean>
            <stddev>2e-3</stddev>
          </noise>
        </x>
        <y>
          <noise type="gaussian">
            <mean>0.0</mean>
            <stddev>2e-3</stddev>
          </noise>
        </y>
        <z>
          <noise type="gaussian">
            <mean>0.0</mean>
            <stddev>2e-3</stddev>
          </noise>
        </z>
      </orientation>
      <angular_velocity>
        <x>
          <noise type="gaussian">
            <mean>0.0</mean>
            <stddev>2e-4</stddev>
          </noise>
        </x>
        <y>
          <noise type="gaussian">
            <mean>0.0</mean>
            <stddev>2e-4</stddev>
          </noise>
        </y>
        <z>
          <noise type="gaussian">
            <mean>0.0</mean>
            <stddev>2e-4</stddev>
          </noise>
        </z>
      </angular_velocity>
      <linear_acceleration>
        <x>
          <noise type="gaussian">
            <mean>0.0</mean>
            <stddev>1.7e-2</stddev>
          </noise>
        </x>
        <y>
          <noise type="gaussian">
            <mean>0.0</mean>
            <stddev>1.7e-2</stddev>
          </noise>
        </y>
        <z>
          <noise type="gaussian">
            <mean>0.0</mean>
            <stddev>1.7e-2</stddev>
          </noise>
        </z>
      </linear_acceleration>
    </imu>

    <!-- Modern Gazebo Sim plugin -->
    <plugin name="imu" filename="gz-sim-imu-system">
      <topic>imu/data</topic>
      <frame_id>imu_link</frame_id>
    </plugin>
  </sensor>
</gazebo>
  <gazebo reference="laser_link">
  <sensor name="laser" type="ray">
    <always_on>true</always_on>
    <visualize>true</visualize>
    <update_rate>10</update_rate>
    <ray>
      <scan>
        <horizontal>
          <samples>120</samples>
          <resolution>1.0</resolution>
          <min_angle>-3.14159</min_angle>
          <max_angle>3.14159</max_angle>
        </horizontal>
      </scan>
      <range>
        <min>0.3</min>
        <max>15.0</max>
        <resolution>0.015</resolution>
      </range>
      <noise>
        <type>gaussian</type>
        <mean>0.0</mean>
        <stddev>0.01</stddev>
      </noise>
    </ray>

    <!-- Modern Gazebo Sim plugin -->
    <plugin name="laser" filename="gz-sim-ray-sensor-system">
      <topic>scan</topic>
      <frame_id>laser_link</frame_id>
    </plugin>
  </sensor>
</gazebo>

  <gazebo reference="front_left_wheel">
    <mu1>100</mu1>
    <mu2>100</mu2>
    <kp>10000000.0</kp>
    <kd>1.0</kd>
    <minDepth>0.01</minDepth>
    <fdir1>1 0 0</fdir1>
    <maxContacts value="64"/>
  </gazebo>
  <gazebo reference="front_right_wheel">
    <mu1>100</mu1>
    <mu2>100</mu2>
    <kp>10000000.0</kp>
    <kd>1.0</kd>
    <minDepth>0.01</minDepth>
    <fdir1>1 0 0</fdir1>
    <maxContacts value="64"/>
  </gazebo>
  <gazebo reference="rear_left_wheel">
    <mu1>100</mu1>
    <mu2>100</mu2>
    <kp>10000000.0</kp>
    <kd>1.0</kd>
    <minDepth>0.01</minDepth>
    <fdir1>1 0 0</fdir1>
    <maxContacts value="64"/>
  </gazebo>
  <gazebo reference="rear_right_wheel">
    <mu1>100</mu1>
    <mu2>100</mu2>
    <kp>10000000.0</kp>
    <kd>1.0</kd>
    <minDepth>0.01</minDepth>
    <fdir1>1 0 0</fdir1>
    <maxContacts value="64"/>
  </gazebo>
  <gazebo>
  <plugin name="diff_drive" filename="gz-sim-diff-drive-system">
    <update_rate>50</update_rate>

    <!-- Wheels -->
    <left_joint>front_left_wheel</left_joint>
    <right_joint>front_right_wheel</right_joint>
    <left_joint>rear_left_wheel</left_joint>
    <right_joint>rear_right_wheel</right_joint>

    <!-- Wheel properties -->
    <wheel_separation>0.172</wheel_separation>
    <wheel_radius>0.045</wheel_radius> <!-- radius instead of diameter -->

    <!-- Limits -->
    <max_wheel_torque>20</max_wheel_torque>
    <max_wheel_acceleration>1.0</max_wheel_acceleration>

    <!-- ROS 2 / transport interface -->
    <topic>cmd_vel</topic>
    <odom_topic>odom</odom_topic>
    <frame_id>odom</frame_id>
    <child_frame_id>base_link</child_frame_id>
  </plugin>
</gazebo>
  <gazebo reference="depth_camera_link">
  <sensor name="depth_camera" type="camera">
    <always_on>true</always_on>
    <update_rate>10</update_rate>
    <camera name="limo_camera">
      <horizontal_fov>1.3962634</horizontal_fov>
      <image>
        <width>640</width>
        <height>480</height>
        <format>R8G8B8</format>
      </image>
      <clip>
        <near>0.02</near>
        <far>50.0</far>
      </clip>
      <!-- Optional distortion model -->
      <distortion>
        <k1>0.1</k1>
        <k2>0.2</k2>
        <k3>0.3</k3>
        <p1>0.4</p1>
        <p2>0.5</p2>
        <center>0.5 0.5</center>
      </distortion>
    </camera>

    <!-- Modern Gazebo Sim plugin -->
    <plugin name="depth_camera" filename="gz-sim-depth-camera-system">
      <topic>camera/depth</topic>
      <frame_id>depth_camera_link</frame_id>
    </plugin>
  </sensor>
</gazebo>

</robot>
